Workbook

Sheet Peça Orçamentária - Analítica
A1: ESTUDO DE ORÇAMENTO 2025
A2: ITEM DE DESPESA | B2: 2025 - 10,5 % | C2: 2025 - 10,5 % | D2: RESULTADO | E2: PROPOSTA 2026
B3: ORÇADO | C3: REALIZADO | D3: 2024 | E3: 10,00 | F3: Contratação de:
A4: DESPESAS GERAIS COM PESSOAL | B4: =B6+B11+B16+B21+B24 -> 1561450 | C4: =C6+C11+C16+C21+C24 -> 1187825.1 | D4: =B4-C4 -> 373624.88 | E4: =E6+E11+E16+E21+E24 -> 1958500 | F4: 01 Supervisor de Segurança
A5: DA ADM / MANUTENÇÃO | F5: 01 Auxiliar Administrativa
A6: TOTAL SALÁRIOS E ENCARGOS | B6: =SUM(B7:B10) -> 961800 | C6: =SUM(C7:C10) -> 839206.34 | D6: =SUM(D7:D10) -> 122593.66 | E6: =SUM(E7:E10) -> 1149000 | F6: 01 Faxineira
A7: Salários / Adicionais / Horas Extras | B7: 710000 | C7: 608756.22 | D7: =B7-C7 -> 101243.78 | E7: 850000
A8: INSS - 25,5% | B8: 182000 | C8: 170223.99 | D8: =B8-C8 -> 11776.01 | E8: 220000
A9: FGTS - 8% | B9: 61000 | C9: 53559.5 | D9: =B9-C9 -> 7440.5 | E9: 70000
A10: PIS - 1% | B10: 8800 | C10: 6666.63 | D10: =B10-C10 -> 2133.37 | E10: 9000
A11: TOTAL FÉRIAS E ENCARGOS | B11: =SUM(B12:B15) -> 126440 | C11: =SUM(C12:C15) -> 100491.61 | D11: =SUM(D12:D15) -> 33581.67 | E11: =SUM(E12:E15) -> 130000
A12: Férias - 33,33% | B12: 94000 | C12: 76198.4 | D12: =B12-C12 -> 17801.6 | E12: 95000
A13: INSS - 25,5% | B13: 24000 | C13: 17955.87 | D13: =B13-C13 -> 6044.13 | E13: 25000
A14: FGTS - 8% | B14: 7500 | C14: 5633.28 | D14: 9500 | E14: 8500
A15: PIS - 1% | B15: 940 | C15: 704.06 | D15: =B15-C15 -> 235.94 | E15: 1500
A16: TOTAL 13.º SALÁRIO E ENCARGOS | B16: =SUM(B17:B20) -> 83880 | C16: =SUM(C17:C20) -> 72693.47 | D16: =SUM(D17:D20) -> 11186.53 | E16: =SUM(E17:E20) -> 103500
A17: 13.º Salário | B17: 61000 | C17: 54422.33 | D17: =B17-C17 -> 6577.67 | E17: 75000
A18: INSS - 25,5% | B18: 16500 | C18: 13504.79 | D18: =B18-C18 -> 2995.21 | E18: 20000
A19: FGTS - 8% | B19: 5500 | C19: 4236.84 | D19: =B19-C19 -> 1263.16 | E19: 7000
A20: PIS - 1% | B20: 880 | C20: 529.51 | D20: =B20-C20 -> 350.49 | E20: 1500
A21: PROVISÕES TRABALHISTAS | B21: =B22+B23 -> 19250 | C21: =C22+C23 -> 0 | D21: =D22+D23 -> 19250 | E21: =E22+E23 -> 102500
A22: Provisões Ações Trabalhistas | B22: 17600 | D22: =B22-C22 -> 17600 | E22: 100000
A23: Exames Médicos | B23: 1650 | D23: =B23-C23 -> 1650 | E23: 2500
A24: BENEFÍCIOS | B24: =SUM(B25:B33) -> 370080 | C24: =SUM(C25:C33) -> 175433.7 | D24: =SUM(D25:D33) -> 194646.3 | E24: =SUM(E25:E33) -> 473500
A25: Vale Transporte | B25: 12000 | C25: 8923.74 | D25: =B25-C25 -> 3076.26 | E25: 16000
A26: Vale Cesta | B26: 63500 | D26: =B26-C26 -> 63500 | E26: 80000
A27: Vale Refeição | B27: 76000 | D27: =B27-C27 -> 76000 | E27: 92000
A28: Cesta de Natal / VR Natal | B28: 25500 | D28: =B28-C28 -> 25500 | E28: 26000
A29: Assistencia Médica / Odontológica | B29: 155000 | C29: 144858.27 | D29: =B29-C29 -> 10141.73 | E29: 210000
A30: Seguro de Vida | B30: 2880 | C30: 3240 | D30: =B30-C30 -> -360 | E30: 1500
A31: Treinamentos/Cursos/Bolsa Educação | B31: 7000 | C31: 7375.02 | D31: =B31-C31 -> -375.02 | E31: 12000
A32: Uniformes | B32: 14100 | C32: 11036.67 | D32: =B32-C32 -> 3063.33 | E32: 18000
A33: Equipamentos de Proteção Individual | B33: 14100 | D33: =B33-C33 -> 14100 | E33: 18000
A34: OUTRAS DESPESAS ADMINISTRATIVAS | B34: =SUM(B35:B58) -> 264040 | C34: =SUM(C35:C58) -> 173660.77 | D34: =SUM(D35:D58) -> 79558.23 | E34: =SUM(E35:E58) -> 274200
A35: Cartórios e Emolumentos | B35: 4500 | C35: 1077.83 | D35: =B35-C35 -> 3422.17 | E35: 5000
A36: Seguro Patrimonial | B36: 6000 | C36: 4735.66 | D36: =B36-C36 -> 1264.34 | E36: 6500
A37: Publicação (Edital) | B37: 1800 | C37: 362 | D37: =B37-C37 -> 1438 | E37: 2500
A38: Material de Escritório | B38: 5900 | C38: 6158.29 | D38: =B38-C38 -> -258.29 | E38: 7000
A39: Material Copa e Cozinha | B39: 29500 | C39: 30419.17 | D39: =B39-C39 -> -919.17 | E39: 33000
A40: Despesas com Reuniões / AGO / AGE | B40: 11000 | D40: =B40-C40 -> 11000 | E40: 12000
...

Sheet Peça Orçamentária - Sintética
A1: ESTUDO DE ORÇAMENTO 2026 | F1: PROPOSTA DE REDUÇÃO NAS DIRETORIAS
A2: ITEM DE DESPESA | B2: 2025 - 10,5 % | C2: 2025 - 10,5 % | D2: RESULTADO | E2: PROPOSTA 2026
B3: ORÇADO | C3: REALIZADO | D3: 2025 | E3: 10,00
A4: DESPESAS GERAIS COM PESSOAL - ADM / MANUTENÇÃO | B4: ='Peça Orçamentária - Analítica'!B4:B5 -> 1561450 | C4: ='Peça Orçamentária - Analítica'!C4:C5 -> 1187825.1 | D4: ='Peça Orçamentária - Analítica'!D4:D5 -> 373624.88 | E4: ='Peça Orçamentária - Analítica'!E4:E5 -> 1958500
A5: OUTRAS DESPESAS ADMINISTRATIVAS | B5: ='Peça Orçamentária - Analítica'!B34 -> 264040 | C5: ='Peça Orçamentária - Analítica'!C34 -> 173660.77 | D5: ='Peça Orçamentária - Analítica'!D34 -> 79558.23 | E5: ='Peça Orçamentária - Analítica'!E34 -> 274200 | F5: Dir Administrativa | G5: 0.04 | H5: =2008500*4% -> 80340
A6: SERVIÇOS DE TERCEIROS | B6: ='Peça Orçamentária - Analítica'!B59 -> 285400 | C6: ='Peça Orçamentária - Analítica'!C59 -> 195771.79 | D6: ='Peça Orçamentária - Analítica'!D59 -> 89628.21 | E6: ='Peça Orçamentária - Analítica'!E59 -> 290300 | F6: Dir Segurança | G6: 0.04 | H6: =5821200*4% -> 232848
A7: MANUTENÇÃO AREAS COMUNS | B7: ='Peça Orçamentária - Analítica'!B73 -> 1079700 | C7: ='Peça Orçamentária - Analítica'!C73 -> 1026244.3 | D7: ='Peça Orçamentária - Analítica'!D73 -> 53455.71 | E7: ='Peça Orçamentária - Analítica'!E73 -> 1191000 | F7: Dir Manut. Obras | G7: 0.1 | H7: =1206000*10% -> 120600
A8: SEGURANÇA | B8: ='Peça Orçamentária - Analítica'!B87 -> 6191000 | C8: ='Peça Orçamentária - Analítica'!C87 -> 5222296.8 | D8: ='Peça Orçamentária - Analítica'!D87 -> 968703.2 | E8: ='Peça Orçamentária - Analítica'!E87 -> 5601200 | F8: Dir Social | G8: 0.2 | H8: =401000*20% -> 80200
A9: DESPESAS COM VEÍCULOS | B9: ='Peça Orçamentária - Analítica'!B96 -> 21600 | C9: ='Peça Orçamentária - Analítica'!C96 -> 8145.96 | D9: ='Peça Orçamentária - Analítica'!D96 -> 13454.04 | E9: ='Peça Orçamentária - Analítica'!E96 -> 21600
A10: EVENTOS SOCIAIS/ESPORTIVOS | B10: ='Peça Orçamentária - Analítica'!B100 -> 464700 | C10: ='Peça Orçamentária - Analítica'!C100 -> 170334.6 | D10: ='Peça Orçamentária - Analítica'!D100 -> 294365.4 | E10: ='Peça Orçamentária - Analítica'!E100 -> 484000 | F10: TOTAL | H10: =SUM(H5:H9) -> 513988
A11: INVESTIMENTOS | B11: ='Peça Orçamentária - Analítica'!B113 -> 1118000 | C11: ='Peça Orçamentária - Analítica'!C113 -> 3791029.5 | D11: ='Peça Orçamentária - Analítica'!D113 -> -2673029.5 | E11: ='Peça Orçamentária - Analítica'!E113 -> 1803500
A12: IMPOSTOS TAXAS E CONTRIBUIÇÕES | B12: ='Peça Orçamentária - Analítica'!B122 -> 476500 | C12: ='Peça Orçamentária - Analítica'!C122 -> 499750.89 | D12: ='Peça Orçamentária - Analítica'!D122 -> -23250.89 | E12: ='Peça Orçamentária - Analítica'!E122 -> 560500
A13: DESPESAS FINANCEIRAS | B13: ='Peça Orçamentária - Analítica'!B128 -> 23520 | C13: ='Peça Orçamentária - Analítica'!C128 -> 29110.44 | D13: ='Peça Orçamentária - Analítica'!D128 -> -5590.44 | E13: ='Peça Orçamentária - Analítica'!E128 -> 19000
A14: TOTAL DESPESAS | B14: ='Peça Orçamentária - Analítica'!B132 -> 11485910 | C14: ='Peça Orçamentária - Analítica'!C132 -> 12304170 | D14: ='Peça Orçamentária - Analítica'!D132 -> -821447.86 | E14: ='Peça Orçamentária - Analítica'!E132 -> 12203800
A16: CONTAS - RECEITAS | B16: 2025 - 10,5 % | C16: 2025 - 10,5 % | D16: RESULTADO | E16: PROPOSTA 2026
B17: ORÇADO | C17: REALIZADO | D17: 2025 | E17: 10,00
A18: TAXA DE MANUTENÇÃO - FATURAMENTO | B18: ='Peça Orçamentária - Analítica'!B137 -> 11079955 | C18: ='Peça Orçamentária - Analítica'!C137 -> 10584462 | D18: ='Peça Orçamentária - Analítica'!D137 -> -495493.45 | E18: ='Peça Orçamentária - Analítica'!E137 -> 12187950
A19: RECEITAS FINANCEIRAS DIVERSAS | B19: ='Peça Orçamentária - Analítica'!B140 -> 327000 | C19: ='Peça Orçamentária - Analítica'!C140 -> 591779.95 | D19: ='Peça Orçamentária - Analítica'!D140 -> 264779.95 | E19: ='Peça Orçamentária - Analítica'!E140 -> 301700
A20: TOTAL GERAL DE RECEITAS | B20: ='Peça Orçamentária - Analítica'!B146 -> 11027387 | C20: ='Peça Orçamentária - Analítica'!C146 -> 10521816 | D20: ='Peça Orçamentária - Analítica'!D146 -> -505571.09 | E20: ='Peça Orçamentária - Analítica'!E146 -> 12220126
